<?xml version="1.0" ?>
<!-- =================================================================================== -->
<!-- |    This document was autogenerated by xacro from seven_dof_arm.xacro            | -->
<!-- |    EDITING THIS FILE BY HAND IS NOT RECOMMENDED                                 | -->
<!-- =================================================================================== -->
<robot name="seven_dof_arm">
  <!-- Include materials -->
  <material name="Black">
    <color rgba="0.0 0.0 0.0 1.0"/>
  </material>
  <material name="Red">
    <color rgba="1.0 0.0 0.0 1.0"/>
  </material>
  <material name="White">
    <color rgba="1.0 1.0 1.0 1.0"/>
  </material>
  <!-- xacro:property -->
  <!-- Links -->
  <!-- BOTTOM_LINK -->
  <link name="bottom_link">
    <visual>
      <origin rpy="0.0 0.0 0.0" xyz="0.0 0.0 -0.01"/>
      <geometry>
        <box size="1 1 0.02"/>
      </geometry>
      <material name="Black"/>
    </visual>
    <collision>
      <origin rpy="0.0 0.0 0.0" xyz="0 0 -0.04"/>
      <geometry>
        <box size="1 1 0.02"/>
      </geometry>
    </collision>
    <inertial>
      <mass value="1"/>
      <inertia ixx="1.0" ixy="0.0" ixz="0.0" iyy="0.5" iyz="0.0" izz="1.0"/>
    </inertial>
  </link>
  <!-- BOTTOM_JOINT -->
  <joint name="bottom_joint" type="fixed">
    <origin rpy="0.0 0.0 0.0" xyz="0.0 0.0 0.0"/>
    <parent link="base_link"/>
    <child link="bottom_link"/>
  </joint>
  <!-- BASE_LINK -->
  <link name="base_link">
    <visual>
      <origin rpy="1.570795 0.0 0.0" xyz="0 0 0.05"/>
      <geometry>
        <box size="0.1 0.1 0.1"/>
      </geometry>
      <material name="White"/>
    </visual>
    <collision>
      <origin rpy="1.570795 0.0 0.0" xyz="0.0 0.0 0.0"/>
      <geometry>
        <box size="0.1 0.1 0.1"/>
      </geometry>
    </collision>
  </link>
  <!-- SHOULDER_PAN_JOINT -->
  <joint name="shoulder_pan_joint" type="revolute">
    <parent link="base_link"/>
    <child link="shoulder_pan_link"/>
    <limit effort="300" lower="-2.61799387799" upper="1.98394848567" velocity="1"/>
    <origin rpy="0.0 0.0 0.0" xyz="0.0 0.0 0.1"/>
    <axis xyz="0 0 1"/>
    <dynamics damping="50" friction="1"/>
  </joint>
  <!-- SHOULDER_PAN_LINK -->
  <link name="shoulder_pan_link">
    <visual>
      <origin rpy="0.0 0.0 0.0" xyz="0.0 0.0 0.0"/>
      <geometry>
        <cylinder length="0.08" radius="0.04"/>
      </geometry>
    </visual>
    <collision>
      <origin rpy="0.0 1.570795 0.0" xyz="0.0 0.0 0.0"/>
      <geometry>
        <cylinder length="0.08" radius="0.04"/>
      </geometry>
    </collision>
    <inertial>
      <mass value="1"/>
      <inertia ixx="1.0" ixy="0.0" ixz="0.0" iyy="0.5" iyz="0.0" izz="1.0"/>
    </inertial>
  </link>
  <!-- SHOULDER_PITCH_JOINT -->
  <joint name="shoulder_pitch_joint" type="revolute">
    <parent link="shoulder_pan_link"/>
    <child link="shoulder_pitch_link"/>
    <limit effort="300" lower="-1.19962513147" upper="1.89994105047" velocity="1"/>
    <origin rpy="0.0 0.0 0.0" xyz="0.0 0.0 0.04"/>
  </joint>
  <!-- SHOULDER_PITCH_LINK -->
  <link name="shoulder_pitch_link">
    <visual>
      <origin rpy="0.0 1.570795 0.0" xyz="0.0 0.0 0.08"/>
      <geometry>
        <box size="0.14 0.04 0.04"/>
      </geometry>
      <material name="White"/>
    </visual>
    <collision>
      <origin rpy="0.0 1.570795 0.0" xyz="0.0 0.0 0.08"/>
      <geometry>
        <box size="0.14 0.04 0.04"/>
      </geometry>
    </collision>
    <inertial>
      <mass value="1"/>
      <inertia ixx="1.0" ixy="0.0" ixz="0.0" iyy="0.5" iyz="0.0" izz="1.0"/>
    </inertial>
  </link>
  <!-- ELBOW_ROLL_JOINT -->
  <joint name="elbow_roll_joint" type="revolute">
    <parent link="shoulder_pitch_link"/>
    <child link="elbow_roll_link"/>
    <limit effort="300" lower="-2.61799387799" upper="0.705631162427" velocity="1"/>
    <origin rpy="0.0 0.0 0.0" xyz="0.0 0.0 0.14"/>
    <axis xyz="0.0 0.0 1.0"/>
    <dynamics damping="50" friction="1"/>
  </joint>
  <!-- ELBOW_ROLL_LINK -->
  <link name="elbow_roll_link">
    <visual>
      <origin rpy="0.0 0.0 0.0" xyz="0.0 0.0 0.0"/>
      <geometry>
        <cylinder length="0.06" radius="0.02"/>
      </geometry>
      <material name="Black"/>
    </visual>
    <collision>
      <origin rpy="0.0 0.0 0.0" xyz="0.0 0.0 0.0"/>
      <geometry>
        <cylinder length="0.06" radius="0.02"/>
      </geometry>
    </collision>
    <inertial>
      <mass value="1"/>
      <inertia ixx="1.0" ixy="0.0" ixz="0.0" iyy="0.5" iyz="0.0" izz="1.0"/>
    </inertial>
  </link>
  <!-- ELBOW_PITCH_JOINT -->
  <joint name="elbow_pitch_joint" type="revolute">
    <parent link="elbow_roll_link"/>
    <child link="elbow_pitch_link"/>
    <limit effort="300" lower="-1.5953400194" upper="1.93281579274" velocity="1"/>
    <origin rpy="0.0 0.0 0.0" xyz="0.0 0.0 0.03"/>
    <dynamics damping="50" friction="1"/>
  </joint>
  <!-- ELBOW_PITCH_LINK -->
  <link name="elbow_pitch_link">
    <visual>
      <origin rpy="0.0 1.570795 0.0" xyz="0.0 0.0 0.11"/>
      <geometry>
        <box size="0.22 0.04 0.04"/>
      </geometry>
    </visual>
    <collision>
      <origin rpy="0.0 1.570795 0.0" xyz="0.0 0.0 0.11"/>
      <geometry>
        <box size="0.22 0.04 0.04"/>
      </geometry>
      <material name="Red"/>
    </collision>
    <inertial>
      <mass value="1"/>
      <inertia ixx="1.0" ixy="0.0" ixz="0.0" iyy="0.5" iyz="0.0" izz="1.0"/>
    </inertial>
  </link>
  <!-- WRIST_ROLL_JOINT -->
  <joint name="wrist_roll_joint" type="revolute">
    <parent link="elbow_pitch_link"/>
    <child link="wrist_roll_link"/>
    <limit effort="300" lower="-2.61799387799" upper="2.6128806087" velocity="1"/>
    <origin rpy="0.0 0.0 0.0" xyz="0.0 0.0 0.22"/>
    <axis xyz="0.0 0.0 1"/>
    <dynamics damping="50" friction="1"/>
  </joint>
  <!-- WRIST_ROLL_LINK -->
  <link name="wrist_roll_link">
    <visual>
      <origin rpy="0.0 0.0 0.0" xyz="0.0 0.0 0"/>
      <geometry>
        <cylinder length="0.04" radius="0.02"/>
      </geometry>
      <material name="Black"/>
    </visual>
    <collision>
      <origin rpy="0.0 0.0 0.0" xyz="0.0 0.0 0"/>
      <geometry>
        <cylinder length="0.04" radius="0.02"/>
      </geometry>
    </collision>
    <inertial>
      <mass value="1"/>
      <inertia ixx="1.0" ixy="0.0" ixz="0.0" iyy="0.5" iyz="0.0" izz="1.0"/>
    </inertial>
  </link>
  <!-- WRIST_PITCH_JOINT -->
  <joint name="wrist_pitch_joint" type="revolute">
    <parent link="wrist_roll_link"/>
    <child link="wrist_pitch_link"/>
    <origin rpy="0.0 0.0 0.0" xyz="0.0 0.0 0.02"/>
    <limit effort="300" lower="-1.5953400194" upper="1.98394848567" velocity="1"/>
    <dynamics damping="50" friction="1"/>
  </joint>
  <!-- WRIST_PITCH_LINK -->
  <link name="wrist_pitch_link">
    <visual>
      <origin rpy="0.0 1.570795 0.0" xyz="0.0 0.0 0.03"/>
      <geometry>
        <box size="0.06 0.04 0.04"/>
      </geometry>
      <material name="White"/>
    </visual>
    <collision>
      <origin rpy="0.0 1.570795 0.0" xyz="0.0 0.0 0.03"/>
      <geometry>
        <box size="0.06 0.04 0.04"/>
      </geometry>
    </collision>
    <inertial>
      <mass value="1"/>
      <inertia ixx="1.0" ixy="0.0" ixz="0.0" iyy="0.5" iyz="0.0" izz="1.0"/>
    </inertial>
  </link>
  <!-- GRIPPER_ROLL_JOINT -->
  <joint name="gripper_roll_joint" type="revolute">
    <parent link="wrist_pitch_link"/>
    <child link="gripper_roll_link"/>
    <origin rpy="0.0 0.0 0.0" xyz="0.0 0.0 0.06"/>
    <axis xyz="0.0 0.0 1.0"/>
    <limit effort="300" lower="-3.14" upper="3.14" velocity="1"/>
    <dynamics damping="50" friction="1"/>
  </joint>
  <!-- GRIPPER_ROLL_LINK -->
  <link name="gripper_roll_link">
    <visual>
      <origin rpy="0.0 0.0 0.0" xyz="0.0 0.0 0.0"/>
      <geometry>
        <cylinder length="0.02" radius="0.04"/>
      </geometry>
      <material name="Red"/>
    </visual>
    <collision>
      <origin rpy="0.0 0.0 0.0" xyz="0.0 0.0 0.0"/>
      <geometry>
        <cylinder length="0.02" radius="0.04"/>
      </geometry>
    </collision>
    <inertial>
      <mass value="1"/>
      <inertia ixx="1.0" ixy="0.0" ixz="0.0" iyy="0.5" iyz="0.0" izz="1.0"/>
    </inertial>
  </link>
  <!-- Finger_joint_1 -->
  <joint name="finger_joint1" type="prismatic">
    <parent link="gripper_roll_link"/>
    <child link="gripper_finger_link1"/>
    <limit effort="100" lower="0" upper="0.03" velocity="1.0"/>
    <origin rpy="0.0 0.0 0.0" xyz="0.0 0.0 0.01"/>
    <axis xyz="1 0.0 0.0"/>
    <dynamics damping="50" friction="1"/>
  </joint>
  <!-- LEFT_GRIPPER_LINK -->
  <link name="gripper_finger_link1">
    <visual>
      <origin rpy="0.0 1.570795 0.0" xyz="0.005 0.0 0.04"/>
      <geometry>
        <box size="0.08 0.01 0.01"/>
      </geometry>
      <material name="White"/>
    </visual>
    <collision>
      <origin rpy="0.0 0.0 0.0" xyz="0.0 0.0 0.0"/>
      <geometry>
        <box size="0.08 0.01 0.01"/>
      </geometry>
    </collision>
  </link>
  <!-- Finger_joint_2 -->
  <joint name="finger_joint2" type="prismatic">
    <parent link="gripper_roll_link"/>
    <child link="gripper_finger_link2"/>
    <limit effort="100" lower="0" upper="0.03" velocity="1.0"/>
    <origin rpy="0.0 0.0 0.0" xyz="0.0 0.0 0.01"/>
    <axis xyz="-1 0.0 0.0"/>
    <dynamics damping="50" friction="1"/>
  </joint>
  <!-- RIGHT_GRIPPER_LINK -->
  <link name="gripper_finger_link2">
    <visual>
      <origin rpy="0.0 1.570795 0.0" xyz="-0.005 0.0 0.04"/>
      <geometry>
        <box size="0.08 0.01 0.01"/>
      </geometry>
      <material name="White"/>
    </visual>
    <collision>
      <origin rpy="0.0 0.0 0.0" xyz="0.0 0.0 0.0"/>
      <geometry>
        <box size="0.08 0.01 0.01"/>
      </geometry>
    </collision>
  </link>
  <!-- Grasping frame -->
  <link name="grasping_frame">
    <visual>
      <origin rpy="0.0 0.0 0.0" xyz="0.0 0.0 0.0"/>
      <geometry>
        <box size="0.01 0.01 0.01"/>
      </geometry>
      <material name="White"/>
    </visual>
    <inertial>
      <origin rpy="0 0 0" xyz="0 0 0"/>
      <mass value="0.0001"/>
      <cuboid_inertia mass="0.0001" x="0.001" y="0.001" z="0.001"/>
      <inertia ixx="1.0" ixy="0.0" ixz="0.0" iyy="100.0" iyz="0.0" izz="1.0"/>
    </inertial>
  </link>
  <joint name="graspingg_frame_joint" type="fixed">
    <parent link="gripper_roll_link"/>
    <child link="grasping_frame"/>
    <origin rpy="0.0 0.0 0.0" xyz="0.0 0.0 0.08"/>
  </joint>
  <transmision name="trans1">
    <type>transmission_interface/SimpleTransmission</type>
    <joint name="shoulder_pan_joint">
      <hardwareInterface>hardware_interface/PositionJointInterface</hardwareInterface>
    </joint>
    <actuator name="motor1">
      <hardwareInterface>hardware_interface/PositionJointInterface</hardwareInterface>
      <mechanicalReduction>1</mechanicalReduction>
    </actuator>
  </transmision>
  <transmision name="trans1">
    <type>transmission_interface/SimpleTransmission</type>
    <joint name="shoulder_pitch_joint">
      <hardwareInterface>hardware_interface/PositionJointInterface</hardwareInterface>
    </joint>
    <actuator name="motor1">
      <hardwareInterface>hardware_interface/PositionJointInterface</hardwareInterface>
      <mechanicalReduction>1</mechanicalReduction>
    </actuator>
  </transmision>
  <transmision name="trans1">
    <type>transmission_interface/SimpleTransmission</type>
    <joint name="elbow_roll_joint">
      <hardwareInterface>hardware_interface/PositionJointInterface</hardwareInterface>
    </joint>
    <actuator name="motor1">
      <hardwareInterface>hardware_interface/PositionJointInterface</hardwareInterface>
      <mechanicalReduction>1</mechanicalReduction>
    </actuator>
  </transmision>
  <transmision name="trans1">
    <type>transmission_interface/SimpleTransmission</type>
    <joint name="elbow_pitch_joint">
      <hardwareInterface>hardware_interface/PositionJointInterface</hardwareInterface>
    </joint>
    <actuator name="motor1">
      <hardwareInterface>hardware_interface/PositionJointInterface</hardwareInterface>
      <mechanicalReduction>1</mechanicalReduction>
    </actuator>
  </transmision>
  <transmision name="trans1">
    <type>transmission_interface/SimpleTransmission</type>
    <joint name="wrist_roll_joint">
      <hardwareInterface>hardware_interface/PositionJointInterface</hardwareInterface>
    </joint>
    <actuator name="motor1">
      <hardwareInterface>hardware_interface/PositionJointInterface</hardwareInterface>
      <mechanicalReduction>1</mechanicalReduction>
    </actuator>
  </transmision>
  <transmision name="trans1">
    <type>transmission_interface/SimpleTransmission</type>
    <joint name="wrist_pitch_joint">
      <hardwareInterface>hardware_interface/PositionJointInterface</hardwareInterface>
    </joint>
    <actuator name="motor1">
      <hardwareInterface>hardware_interface/PositionJointInterface</hardwareInterface>
      <mechanicalReduction>1</mechanicalReduction>
    </actuator>
  </transmision>
  <transmision name="trans1">
    <type>transmission_interface/SimpleTransmission</type>
    <joint name="gripper_roll_joint">
      <hardwareInterface>hardware_interface/PositionJointInterface</hardwareInterface>
    </joint>
    <actuator name="motor1">
      <hardwareInterface>hardware_interface/PositionJointInterface</hardwareInterface>
      <mechanicalReduction>1</mechanicalReduction>
    </actuator>
  </transmision>
  <transmision name="trans1">
    <type>transmission_interface/SimpleTransmission</type>
    <joint name="finger_joint1">
      <hardwareInterface>hardware_interface/PositionJointInterface</hardwareInterface>
    </joint>
    <actuator name="motor1">
      <hardwareInterface>hardware_interface/PositionJointInterface</hardwareInterface>
      <mechanicalReduction>1</mechanicalReduction>
    </actuator>
  </transmision>
  <transmision name="trans1">
    <type>transmission_interface/SimpleTransmission</type>
    <joint name="finger_joint1">
      <hardwareInterface>hardware_interface/PositionJointInterface</hardwareInterface>
    </joint>
    <actuator name="motor1">
      <hardwareInterface>hardware_interface/PositionJointInterface</hardwareInterface>
      <mechanicalReduction>1</mechanicalReduction>
    </actuator>
  </transmision>
  <!-- ROS control plugin -->
  <gazebo>
    <plugin filename="libgazebo_ros_control.so" name="gazebo_ros_control">
      <robotNamespace>seven_dof_arm</robotNamespace>
    </plugin>
  </gazebo>
</robot>

